<?xml version="1.0" ?>
<robot name="onrobot_rg2_model">

  <link name="world"/>
  
  <joint name="joint0" type="fixed">
    <parent link="world"/>
    <child link="onrobot_rg2_base_link"/>
    <origin xyz="0.0 0.0 0.0" rpy="0.0 0.0 0.0" />
  </joint>

  <link name="onrobot_rg2_base_link">
    <inertial>
      <origin xyz="0.0 0.0 0.0" rpy="0 0 0" />
      <mass value="0.7" />
      <inertia ixx="1.0E-03" ixy="1.0E-06" ixz="1.0E-06" iyy="1.0E-03" iyz="1.0E-06" izz="1.0E-03" />
    </inertial>
    <visual>
      <origin xyz="0 0 0" rpy="0 0 0" />
      <geometry>
        <mesh filename="package://onrobot_rg2_description/meshes/visual/base_link.stl" />
      </geometry>
      <material name="">
        <color rgba="0.8 0.8 0.8 1" />
      </material>
    </visual>
    <collision>
      <origin xyz="0 0 0" rpy="0 0 0" />
      <geometry>
        <mesh filename="package://onrobot_rg2_description/meshes/collision/base_link.stl" />
      </geometry>
    </collision>
  </link>

  <link name="left_outer_knuckle">
    <inertial>
      <origin xyz="0.0 0.0 0.0" rpy="0 0 0" />
      <mass value="0.05" />
      <inertia ixx="1.0E-03" ixy="1.0E-06" ixz="1.0E-06" iyy="1.0E-03" iyz="1.0E-06" izz="1.0E-03" />
    </inertial>
    <visual>
      <origin xyz="0 0 0" rpy="0 0 0" />
      <geometry>
        <mesh filename="package://onrobot_rg2_description/meshes/visual/outer_knuckle.stl" />
      </geometry>
      <material name="">
        <color rgba="0.8 0.8 0.8 1" />
      </material>
    </visual>
    <collision>
      <origin xyz="0 0 0" rpy="0 0 0" />
      <geometry>
        <mesh filename="package://onrobot_rg2_description/meshes/collision/outer_knuckle.stl" />
      </geometry>
    </collision>
  </link>

  <link name="left_inner_knuckle">
    <inertial>
      <origin xyz="0.0 0.0 0.0" rpy="0 0 0" />
      <mass value="0.05" />
      <inertia ixx="1.0E-03" ixy="1.0E-06" ixz="1.0E-06" iyy="1.0E-03" iyz="1.0E-06" izz="1.0E-03" />
    </inertial>
    <visual>
      <origin xyz="0 0 0" rpy="0 0 0" />
      <geometry>
        <mesh filename="package://onrobot_rg2_description/meshes/visual/inner_knuckle.stl" />
      </geometry>
      <material name="">
        <color rgba="0.8 0.8 0.8 1" />
      </material>
    </visual>
    <collision>
      <origin xyz="0 0 0" rpy="0 0 0" />
      <geometry>
        <mesh filename="package://onrobot_rg2_description/meshes/collision/inner_knuckle.stl" />
      </geometry>
    </collision>
  </link>

  <link name="left_inner_finger">
    <inertial>
      <origin xyz="0.0 0.0 0.0" rpy="0 0 0" />
      <mass value="0.05" />
      <inertia ixx="1.0E-03" ixy="1.0E-06" ixz="1.0E-06" iyy="1.0E-03" iyz="1.0E-06" izz="1.0E-03" />
    </inertial>
    <visual>
      <origin xyz="0 0 0" rpy="0 0 0" />
      <geometry>
        <mesh filename="package://onrobot_rg2_description/meshes/visual/inner_finger.stl" />
      </geometry>
      <material name="">
        <color rgba="0.1 0.1 0.1 1" />
      </material>
    </visual>
    <collision>
      <origin xyz="0 0 0" rpy="0 0 0" />
      <geometry>
        <mesh filename="package://onrobot_rg2_description/meshes/collision/inner_finger.stl" />
      </geometry>
    </collision>
  </link>

  <link name="right_outer_knuckle">
    <inertial>
      <origin xyz="0.0 0.0 0.0" rpy="0 0 0" />
      <mass value="0.05" />
      <inertia ixx="1.0E-03" ixy="1.0E-06" ixz="1.0E-06" iyy="1.0E-03" iyz="1.0E-06" izz="1.0E-03" />
    </inertial>
    <visual>
      <origin xyz="0 0 0" rpy="0 0 0" />
      <geometry>
        <mesh filename="package://onrobot_rg2_description/meshes/visual/outer_knuckle.stl" />
      </geometry>
      <material name="">
        <color rgba="0.8 0.8 0.8 1" />
      </material>
    </visual>
    <collision>
      <origin xyz="0 0 0" rpy="0 0 0" />
      <geometry>
        <mesh filename="package://onrobot_rg2_description/meshes/collision/outer_knuckle.stl" />
      </geometry>
    </collision>
  </link>

  <link name="right_inner_knuckle">
    <inertial>
      <origin xyz="0.0 0.0 0.0" rpy="0 0 0" />
      <mass value="0.05" />
      <inertia ixx="1.0E-03" ixy="1.0E-06" ixz="1.0E-06" iyy="1.0E-03" iyz="1.0E-06" izz="1.0E-03" />
    </inertial>
    <visual>
      <origin xyz="0 0 0" rpy="0 0 0" />
      <geometry>
        <mesh filename="package://onrobot_rg2_description/meshes/visual/inner_knuckle.stl" />
      </geometry>
      <material name="">
        <color rgba="0.8 0.8 0.8 1" />
      </material>
    </visual>
    <collision>
      <origin xyz="0 0 0" rpy="0 0 0" />
      <geometry>
        <mesh filename="package://onrobot_rg2_description/meshes/collision/inner_knuckle.stl" />
      </geometry>
    </collision>
  </link>

  <link name="right_inner_finger">
    <inertial>
      <origin xyz="0.0 0.0 0.0" rpy="0 0 0" />
      <mass value="0.05" />
      <inertia ixx="1.0E-03" ixy="1.0E-06" ixz="1.0E-06" iyy="1.0E-03" iyz="1.0E-06" izz="1.0E-03" />
    </inertial>
    <visual>
      <origin xyz="0 0 0" rpy="0 0 0" />
      <geometry>
        <mesh filename="package://onrobot_rg2_description/meshes/visual/inner_finger.stl" />
      </geometry>
      <material name="">
        <color rgba="0.1 0.1 0.1 1" />
      </material>
    </visual>
    <collision>
      <origin xyz="0 0 0" rpy="0 0 0" />
      <geometry>
        <mesh filename="package://onrobot_rg2_description/meshes/collision/inner_finger.stl" />
      </geometry>
    </collision>
  </link>


  <joint name="finger_joint" type="revolute">
    <origin xyz="0 -0.017178 0.125797" rpy="0 0 0" />
    <parent link="onrobot_rg2_base_link" />
    <child link="left_outer_knuckle" />
    <axis xyz="-1 0 0" />
    <limit lower="-0.558505" upper="0.785398" velocity="100.0" effort="1000" />
  </joint>

  <joint name="left_inner_knuckle_joint" type="revolute">
    <origin xyz="0 -0.007678 0.1422970" rpy="0 0 0" />
    <parent link="onrobot_rg2_base_link" />
    <child link="left_inner_knuckle" />
    <axis xyz="1 0 0" />
    <limit lower="-0.785398" upper="0.785398" velocity="100.0" effort="1000" />
    <mimic joint="finger_joint" multiplier="-1" offset="0" />
  </joint>

  <joint name="left_inner_finger_joint" type="revolute">
    <origin xyz="0 -0.039592 0.038177" rpy="0 0 0" />
    <parent link="left_outer_knuckle" />
    <child link="left_inner_finger" />
    <axis xyz="1 0 0" />
    <limit lower="-0.872665" upper="0.872665" velocity="100.0" effort="1000" />
    <mimic joint="finger_joint" multiplier="1" offset="0" />
  </joint>

  <joint name="right_outer_knuckle_joint" type="revolute">
    <origin xyz="0 0.017178 0.125797" rpy="0 0 3.14159265359" />
    <parent link="onrobot_rg2_base_link" />
    <child link="right_outer_knuckle" />
    <axis xyz="1 0 0" />
    <limit lower="-0.785398" upper="0.785398" velocity="100.0" effort="1000" />
    <mimic joint="finger_joint" multiplier="-1" offset="0" />
  </joint>

  <joint name="right_inner_knuckle_joint" type="revolute">
    <origin xyz="0 0.007678 0.1422970" rpy="0 0 -3.14159265359" />
    <parent link="onrobot_rg2_base_link" />
    <child link="right_inner_knuckle" />
    <axis xyz="1 0 0" />
    <limit lower="-0.785398" upper="0.785398" velocity="100.0" effort="1000" />
    <mimic joint="finger_joint" multiplier="-1" offset="0" />
  </joint>

  <joint name="right_inner_finger_joint" type="revolute">
    <origin xyz="0 -0.039592 0.038177" rpy="0 0 0" />
    <parent link="right_outer_knuckle" />
    <child link="right_inner_finger" />
    <axis xyz="1 0 0" />
    <limit lower="-0.872665" upper="0.872665" velocity="100.0" effort="1000" />
    <mimic joint="finger_joint" multiplier="1" offset="0" />
  </joint>

</robot>